Traceback (most recent call last):
  File "all_of_debugging.py", line 137, in <module>
    raise Exception('This is an error!')
Exception: This is an error!
